Traceback (most recent call last):
  File "C:\Users\M Nur Fauzan W\AppData\Local\Programs\Python\Python39\lib\site-packages\jupyter_cache\executors\utils.py", line 51, in single_nb_execution
    executenb(
  File "C:\Users\M Nur Fauzan W\AppData\Local\Programs\Python\Python39\lib\site-packages\nbclient\client.py", line 1204, in execute
    return NotebookClient(nb=nb, resources=resources, km=km, **kwargs).execute()
  File "C:\Users\M Nur Fauzan W\AppData\Local\Programs\Python\Python39\lib\site-packages\nbclient\util.py", line 84, in wrapped
    return just_run(coro(*args, **kwargs))
  File "C:\Users\M Nur Fauzan W\AppData\Local\Programs\Python\Python39\lib\site-packages\nbclient\util.py", line 62, in just_run
    return loop.run_until_complete(coro)
  File "C:\Users\M Nur Fauzan W\AppData\Local\Programs\Python\Python39\lib\asyncio\base_events.py", line 642, in run_until_complete
    return future.result()
  File "C:\Users\M Nur Fauzan W\AppData\Local\Programs\Python\Python39\lib\site-packages\nbclient\client.py", line 663, in async_execute
    await self.async_execute_cell(
  File "C:\Users\M Nur Fauzan W\AppData\Local\Programs\Python\Python39\lib\site-packages\nbclient\client.py", line 965, in async_execute_cell
    await self._check_raise_for_error(cell, cell_index, exec_reply)
  File "C:\Users\M Nur Fauzan W\AppData\Local\Programs\Python\Python39\lib\site-packages\nbclient\client.py", line 862, in _check_raise_for_error
    raise CellExecutionError.from_cell_and_msg(cell, exec_reply_content)
nbclient.exceptions.CellExecutionError: An error occurred while executing the following cell:
------------------
import matplotlib.pyplot as plt
import networkx as nx
from nltk.probability import DictionaryConditionalProbDist
data = pd.read_csv("preprocessing_summary.csv")
G = nx.DiGraph()
G = nx.from_pandas_edgelist(data,edge_key='',edge_attr='kata',create_using=nx.Graph())
nx.draw(G)
plt.show()
# dataTF.
------------------

[1;31m---------------------------------------------------------------------------[0m
[1;31mKeyError[0m                                  Traceback (most recent call last)
[1;32m~\AppData\Local\Programs\Python\Python39\lib\site-packages\pandas\core\indexes\base.py[0m in [0;36mget_loc[1;34m(self, key, method, tolerance)[0m
[0;32m   3360[0m             [1;32mtry[0m[1;33m:[0m[1;33m[0m[1;33m[0m[0m
[1;32m-> 3361[1;33m                 [1;32mreturn[0m [0mself[0m[1;33m.[0m[0m_engine[0m[1;33m.[0m[0mget_loc[0m[1;33m([0m[0mcasted_key[0m[1;33m)[0m[1;33m[0m[1;33m[0m[0m
[0m[0;32m   3362[0m             [1;32mexcept[0m [0mKeyError[0m [1;32mas[0m [0merr[0m[1;33m:[0m[1;33m[0m[1;33m[0m[0m

[1;32m~\AppData\Local\Programs\Python\Python39\lib\site-packages\pandas\_libs\index.pyx[0m in [0;36mpandas._libs.index.IndexEngine.get_loc[1;34m()[0m

[1;32m~\AppData\Local\Programs\Python\Python39\lib\site-packages\pandas\_libs\index.pyx[0m in [0;36mpandas._libs.index.IndexEngine.get_loc[1;34m()[0m

[1;32mpandas\_libs\hashtable_class_helper.pxi[0m in [0;36mpandas._libs.hashtable.PyObjectHashTable.get_item[1;34m()[0m

[1;32mpandas\_libs\hashtable_class_helper.pxi[0m in [0;36mpandas._libs.hashtable.PyObjectHashTable.get_item[1;34m()[0m

[1;31mKeyError[0m: 'source'

The above exception was the direct cause of the following exception:

[1;31mKeyError[0m                                  Traceback (most recent call last)
[1;32mC:\Users\MNURFA~1\AppData\Local\Temp/ipykernel_4564/2516493177.py[0m in [0;36m<module>[1;34m[0m
[0;32m      4[0m [0mdata[0m [1;33m=[0m [0mpd[0m[1;33m.[0m[0mread_csv[0m[1;33m([0m[1;34m"preprocessing_summary.csv"[0m[1;33m)[0m[1;33m[0m[1;33m[0m[0m
[0;32m      5[0m [0mG[0m [1;33m=[0m [0mnx[0m[1;33m.[0m[0mDiGraph[0m[1;33m([0m[1;33m)[0m[1;33m[0m[1;33m[0m[0m
[1;32m----> 6[1;33m [0mG[0m [1;33m=[0m [0mnx[0m[1;33m.[0m[0mfrom_pandas_edgelist[0m[1;33m([0m[0mdata[0m[1;33m,[0m[0medge_key[0m[1;33m=[0m[1;34m''[0m[1;33m,[0m[0medge_attr[0m[1;33m=[0m[1;34m'kata'[0m[1;33m,[0m[0mcreate_using[0m[1;33m=[0m[0mnx[0m[1;33m.[0m[0mGraph[0m[1;33m([0m[1;33m)[0m[1;33m)[0m[1;33m[0m[1;33m[0m[0m
[0m[0;32m      7[0m [0mnx[0m[1;33m.[0m[0mdraw[0m[1;33m([0m[0mG[0m[1;33m)[0m[1;33m[0m[1;33m[0m[0m
[0;32m      8[0m [0mplt[0m[1;33m.[0m[0mshow[0m[1;33m([0m[1;33m)[0m[1;33m[0m[1;33m[0m[0m

[1;32m~\AppData\Local\Programs\Python\Python39\lib\site-packages\networkx\convert_matrix.py[0m in [0;36mfrom_pandas_edgelist[1;34m(df, source, target, edge_attr, create_using, edge_key)[0m
[0;32m    470[0m             [0mg[0m[1;33m[[0m[0ms[0m[1;33m][0m[1;33m[[0m[0mt[0m[1;33m][0m[1;33m[[0m[0mkey[0m[1;33m][0m[1;33m.[0m[0mupdate[0m[1;33m([0m[0mzip[0m[1;33m([0m[0mattr_col_headings[0m[1;33m,[0m [0mattrs[0m[1;33m)[0m[1;33m)[0m[1;33m[0m[1;33m[0m[0m
[0;32m    471[0m     [1;32melse[0m[1;33m:[0m[1;33m[0m[1;33m[0m[0m
[1;32m--> 472[1;33m         [1;32mfor[0m [0ms[0m[1;33m,[0m [0mt[0m[1;33m,[0m [0mattrs[0m [1;32min[0m [0mzip[0m[1;33m([0m[0mdf[0m[1;33m[[0m[0msource[0m[1;33m][0m[1;33m,[0m [0mdf[0m[1;33m[[0m[0mtarget[0m[1;33m][0m[1;33m,[0m [0mattribute_data[0m[1;33m)[0m[1;33m:[0m[1;33m[0m[1;33m[0m[0m
[0m[0;32m    473[0m             [0mg[0m[1;33m.[0m[0madd_edge[0m[1;33m([0m[0ms[0m[1;33m,[0m [0mt[0m[1;33m)[0m[1;33m[0m[1;33m[0m[0m
[0;32m    474[0m             [0mg[0m[1;33m[[0m[0ms[0m[1;33m][0m[1;33m[[0m[0mt[0m[1;33m][0m[1;33m.[0m[0mupdate[0m[1;33m([0m[0mzip[0m[1;33m([0m[0mattr_col_headings[0m[1;33m,[0m [0mattrs[0m[1;33m)[0m[1;33m)[0m[1;33m[0m[1;33m[0m[0m

[1;32m~\AppData\Local\Programs\Python\Python39\lib\site-packages\pandas\core\frame.py[0m in [0;36m__getitem__[1;34m(self, key)[0m
[0;32m   3456[0m             [1;32mif[0m [0mself[0m[1;33m.[0m[0mcolumns[0m[1;33m.[0m[0mnlevels[0m [1;33m>[0m [1;36m1[0m[1;33m:[0m[1;33m[0m[1;33m[0m[0m
[0;32m   3457[0m                 [1;32mreturn[0m [0mself[0m[1;33m.[0m[0m_getitem_multilevel[0m[1;33m([0m[0mkey[0m[1;33m)[0m[1;33m[0m[1;33m[0m[0m
[1;32m-> 3458[1;33m             [0mindexer[0m [1;33m=[0m [0mself[0m[1;33m.[0m[0mcolumns[0m[1;33m.[0m[0mget_loc[0m[1;33m([0m[0mkey[0m[1;33m)[0m[1;33m[0m[1;33m[0m[0m
[0m[0;32m   3459[0m             [1;32mif[0m [0mis_integer[0m[1;33m([0m[0mindexer[0m[1;33m)[0m[1;33m:[0m[1;33m[0m[1;33m[0m[0m
[0;32m   3460[0m                 [0mindexer[0m [1;33m=[0m [1;33m[[0m[0mindexer[0m[1;33m][0m[1;33m[0m[1;33m[0m[0m

[1;32m~\AppData\Local\Programs\Python\Python39\lib\site-packages\pandas\core\indexes\base.py[0m in [0;36mget_loc[1;34m(self, key, method, tolerance)[0m
[0;32m   3361[0m                 [1;32mreturn[0m [0mself[0m[1;33m.[0m[0m_engine[0m[1;33m.[0m[0mget_loc[0m[1;33m([0m[0mcasted_key[0m[1;33m)[0m[1;33m[0m[1;33m[0m[0m
[0;32m   3362[0m             [1;32mexcept[0m [0mKeyError[0m [1;32mas[0m [0merr[0m[1;33m:[0m[1;33m[0m[1;33m[0m[0m
[1;32m-> 3363[1;33m                 [1;32mraise[0m [0mKeyError[0m[1;33m([0m[0mkey[0m[1;33m)[0m [1;32mfrom[0m [0merr[0m[1;33m[0m[1;33m[0m[0m
[0m[0;32m   3364[0m [1;33m[0m[0m
[0;32m   3365[0m         [1;32mif[0m [0mis_scalar[0m[1;33m([0m[0mkey[0m[1;33m)[0m [1;32mand[0m [0misna[0m[1;33m([0m[0mkey[0m[1;33m)[0m [1;32mand[0m [1;32mnot[0m [0mself[0m[1;33m.[0m[0mhasnans[0m[1;33m:[0m[1;33m[0m[1;33m[0m[0m

[1;31mKeyError[0m: 'source'
KeyError: 'source'

